# 错误处理

与大多数主流编程语言一样，Rust的错误体系也区分 `可恢复错误`和`不可恢复错误`。

## panic!处理不可恢复错误

```rust
fn main() {
    panic!("crash and burn");
}
```

## Result处理可恢复错误

```rust
enum Result<T, E> {
    Ok(T),
    Err(E),
}
```
### 使用match表达式处理

```rust
use std::fs::File;
fn main() {
    let f = File::open("hello.txt");

    let f = match f {
        Ok(file) => file,
        Err(error) => {
            panic!("Problem opening the file: {:?}", error)
        },
    };
}
```
### 更近一步，判断错误类型

```rust
fn main() {
    let f = File::open("hello.txt");

    let f = match f {
        Ok(file) => file,
        Err(error) => match error.kind() {
            ErrorKind::NotFound => match File::create("hello.txt") {
                Ok(fc) => fc,
                Err(e) => panic!("Problem creating the file: {:?}", e),
            },
            other_error => panic!("Problem opening the file: {:?}", other_error),
        },
    };
}
```

更优雅的处理方式：

```rust
fn main() {
    let f = File::open("hello.txt").unwrap_or_else(|error| {
        if error.kind() == ErrorKind::NotFound {
            File::create("hello.txt").unwrap_or_else(|error| {
                panic!("Problem creating the file: {:?}", error);
            })
        } else {
            panic!("Problem opening the file: {:?}", error);
        }
    });
}
```

### unwarp和expect

`unwarp`和`expect`是一种快捷方式，如果存在Error，使用`panic!`处理错误：

```rust
let f = File::open("hello.txt").unwrap();//系统描述错误场景
let f = File::open("hello.txt").expect("Failed to open hello.txt");//自定义错误信息
```

其区别的例子如下
：
```
thread 'main' panicked at 'called `Result::unwrap()` on an `Err` value: Error { 
repr: Os { code: 2, message: "No such file or directory" } }', 
src/libcore/result.rs:906:4

thread 'main' panicked at 'Failed to open hello.txt: Error { repr: Os { code: 
2, message: "No such file or directory" } }', src/libcore/result.rs:906:4
```

### 传播错误

```rust
fn read_username_from_file() -> Result<String, io::Error> {
    let f = File::open("hello.txt");

    let mut f = match f {
        Ok(file) => file,
        Err(e) => return Err(e),
    };

    let mut s = String::new();

    match f.read_to_string(&mut s) {
        Ok(_) => Ok(s),
        Err(e) => Err(e),
    }
}
```

#### 传播错误简写：?运算符

一个减少传播错误的样板代码的语法糖：

```rust
fn read_username_from_file() -> Result<String, io::Error> {
    let mut f = File::open("hello.txt")?;
    let mut s = String::new();
    f.read_to_string(&mut s)?;
    Ok(s)
}
```

还可以这样写：

```rust
fn read_username_from_file() -> Result<String, io::Error> {
    let mut s = String::new();

    File::open("hello.txt")?.read_to_string(&mut s)?;

    Ok(s)
}
```

背后的原理：

>? 运算符所使用的错误值被传递给了 from 函数，它定义于标准库的 From trait 中，其用来将错误从一种类型转换为另一种类型。

如果我们需要在`read_username_from_file`函数中返回自定义错误类型`CustomError`，则需要实现`impl From<io::Error> for CustomError`。

### 仅返回错误

有些场景不需要返回值，仅需要考虑成功或者错误，使用`单元元组`来表示空返回值：

```rust
Result<(),ErrorType>
```

## 真实的错误处理

[anyhow](anyhow简介.md)

## 总结

Rust对于`可恢复错误`的设计是很灵活的，可以是任意类型。这明显不同于传统的强类型、编译型语言。

事实上，标准库只搭建了一个错误处理的基础框架。在实际项目开发中，需要用的第三库和额外的规范来实现错误处理。