# 错误

错误是以`错误集`的形式存在的：

```zig
const FileOpenError = error{//error是个关键字？
    AccessDenied,
    OutOfMemory,
    FileNotFound,
};
```

## 错误联合类型

使用`!`将错误与一个普通类型组合成`错误联合类型`：

```zig
const expect = @import("std").testing.expect;

const AllocationError = error{OutOfMemory};

test "error union" {
    const maybe_error: AllocationError!u16 = 10;
    const no_error = maybe_error catch 0;

    try expect(@TypeOf(no_error) == u16);
    try expect(no_error == 10);
}
```

错误联合类型常用于表示函数的返回值。

```zig
fn failingFunction() error{Oops}!void {
    return error.Oops;// 返回错误值
}
```

## catch错误

虽然错误是值，但是Zig又搞了个catch语法，蛮怪异的。

```zig
const expect = @import("std").testing.expect;

test "returning an error" {
    failingFunction() catch |err| {
        try expect(err == error.Oops);
        return;
    };
}
```

## 错误传播

为了语法上支持错误传播，Zig使用了其它语言错误处理所使用的`try`关键字，但含义明显不同。

`try x `是`x catch |err| {return err}`的语法糖。

```zig
fn failFn() error{Oops}!i32 {
    try failingFunction();
    return 12;
}
```

## errordefer

类似`defer`，如果之后发生错误则执行。

## 错误集推断

```zig
fn createFile() !void {
    return error.AccessDenied;//这是什么语法？
}

test "inferred error set" {
    //type coercion successfully takes place
    const x: error{AccessDenied}!void = createFile();

    //Zig does not let us ignore error unions via _ = x;
    //we must unwrap it with "try", "catch", or "if" by any means
    _ = x catch {};
}
```

这里有两个疑惑：

- `error.AccessDenied`是什么语法？
- 第二个，错误类型推断应用场景是什么，目前我在vscode中测试，目前ZLS还无法推导显示`createFile()`或`x`的错误类型。

## 错误集合并

```zig
const A = error{ NotDir, PathNotFound };
const B = error{ OutOfMemory, PathNotFound };
const C = A || B;
```

## anyerror

`anyerror`是所有错误集的超集，在某些场合会用到（比如兜底）。

## 小结

Zig的错误设计蛮新颖的。
